Workbook

Sheet CATALOGO_PRODUCTOS
A1: SKU | B1: Costo_Base | C1: Descripción | D1: Proveedor | E1: Model | F1: Origen | G1: Categoría | H1: Unidad | I1: Moneda_Base | J1: Fecha_Actualización | K1: Activo (Sí/No) | L1: Costo_Base_MXN | M1: Flete_% | N1: Seguro_% | O1: Arancel_% | P1: Mark_up_% | Q1: DTA | R1: Honorarios_Aduanales | S1: Landed_Cost_MXN | T1: Mark_up
A2: D0031 | B2: 0.0235 | C2: Jeringa estéril desechable | D2: Ander Med | E2: 3mL | F2: Importado | G2: Insumo | H2: Pza | I2: USD | J2: 46030 | K2: No | L2: =tblCatalogo[[#This Row],[Costo_Base]]*21 -> 0.4935
A3: D0051 | B3: 0.029 | C3: Jeringa estéril desechable | D3: Ander Med | E3: 5mL | F3: Importado | G3: Insumo | H3: Pza | I3: USD | J3: 46030 | K3: No | L3: =tblCatalogo[[#This Row],[Costo_Base]]*21 -> 0.609
A4: D0101 | B4: 0.037 | C4: Jeringa estéril desechable | D4: Ander Med | E4: 10mL | F4: Importado | G4: Insumo | H4: Pza | I4: USD | J4: 46030 | K4: No | L4: =tblCatalogo[[#This Row],[Costo_Base]]*21 -> 0.777
A5: D0201 | B5: 0.061 | C5: Jeringa estéril desechable | D5: Ander Med | E5: 20mL | F5: Importado | G5: Insumo | H5: Pza | I5: USD | J5: 46030 | K5: No | L5: =tblCatalogo[[#This Row],[Costo_Base]]*21 -> 1.281
A6: D0501 | B6: 0.121 | C6: Jeringa estéril desechable | D6: Ander Med | E6: 50mL | F6: Importado | G6: Insumo | H6: Pza | I6: USD | J6: 46030 | K6: No | L6: =tblCatalogo[[#This Row],[Costo_Base]]*21 -> 2.541
A7: D0601 | B7: 0.121 | C7: Jeringa estéril desechable | D7: Ander Med | E7: 60mL | F7: Importado | G7: Insumo | H7: Pza | I7: USD | J7: 46030 | K7: No | L7: =tblCatalogo[[#This Row],[Costo_Base]]*21 -> 2.541
A8: D803 | B8: 0.038 | C8: Jeringa desechable resistente a la luz para bomba | D8: Ander Med | E8: 3mL (3ml) | F8: Importado | G8: Insumo | H8: Pza | I8: USD | J8: 46030 | K8: No | L8: =tblCatalogo[[#This Row],[Costo_Base]]*21 -> 0.798
A9: D805 | B9: 0.038 | C9: Jeringa desechable resistente a la luz para bomba | D9: Ander Med | E9: 5mL (5ml) | F9: Importado | G9: Insumo | H9: Pza | I9: USD | J9: 46030 | K9: No | L9: =tblCatalogo[[#This Row],[Costo_Base]]*21 -> 0.798
A10: D810 | B10: 0.046 | C10: Jeringa desechable resistente a la luz para bomba | D10: Ander Med | E10: 10mL (10ml) | F10: Importado | G10: Insumo | H10: Pza | I10: USD | J10: 46030 | K10: No | L10: =tblCatalogo[[#This Row],[Costo_Base]]*21 -> 0.966
A11: D820 | B11: 0.062 | C11: Jeringa desechable resistente a la luz para bomba | D11: Ander Med | E11: 20mL (20ml) | F11: Importado | G11: Insumo | H11: Pza | I11: USD | J11: 46030 | K11: No | L11: =tblCatalogo[[#This Row],[Costo_Base]]*21 -> 1.302
A12: D850 | B12: 0.132 | C12: Jeringa desechable resistente a la luz para bomba | D12: Ander Med | E12: 50mL (50ml) | F12: Importado | G12: Insumo | H12: Pza | I12: USD | J12: 46030 | K12: No | L12: =tblCatalogo[[#This Row],[Costo_Base]]*21 -> 2.772
A13: D860 | B13: 0.132 | C13: Jeringa desechable resistente a la luz para bomba | D13: Ander Med | E13: 60mL (60ml) | F13: Importado | G13: Insumo | H13: Pza | I13: USD | J13: 46030 | K13: No | L13: =tblCatalogo[[#This Row],[Costo_Base]]*21 -> 2.772
... A60: AP-TCI | B60: 900 | C60: Software TCI para instalación en AP-30 | D60: Medcaptain | E60: Equipo médico | F60: Importado | G60: Equipo | H60: Pza | I60: USD | J60: 46030 | K60: Si | L60: =tblCatalogo[[#This Row],[Costo_Base]]*21 -> 18900
A61: Aza HP | B61: N/A | C61: Mango/Aza para equipo serie HP | D61: Medcaptain | E61: Accesorio | F61: Importado | G61: Insumo | H61: Pza | I61: USD | J61: 46030 | K61: Si | L61: =tblCatalogo[[#This Row],[Costo_Base]]*21 -> #VALUE!
A62: Cable alimentacion | B62: N/A | C62: Abrazadera para soporte de bomba HP | D62: Medcaptain | E62: Accesorio | F62: Importado | G62: Insumo | H62: Pza | I62: USD | J62: 46030 | K62: Si | L62: =tblCatalogo[[#This Row],[Costo_Base]]*21 -> #VALUE!
A63: D103121201 | B63: 0 | C63: Jeringa estéril desechable | D63: Ander Med | E63: 3mlluerlock21G×20mmTW (3mlluer lock21G×20mm TW) | F63: Importado | G63: Insumo | H63: Pza | I63: USD | J63: 46030 | K63: No | L63: =tblCatalogo[[#This Row],[Costo_Base]]*21 -> 0
A64: D103121251 | B64: 0 | C64: Jeringa estéril desechable | D64: Ander Med | E64: 3mlluerlock21G×25mmTW (3mlluer lock21G×25mm TW) | F64: Importado | G64: Insumo | H64: Pza | I64: USD | J64: 46030 | K64: No | L64: =tblCatalogo[[#This Row],[Costo_Base]]*21 -> 0
A65: D103121321 | B65: 0 | C65: Jeringa estéril desechable | D65: Ander Med | E65: 3mlluerlock21G×32mmTW (3mlluer lock21G×32mm TW) | F65: Importado | G65: Insumo | H65: Pza | I65: USD | J65: 46030 | K65: No | L65: =tblCatalogo[[#This Row],[Costo_Base]]*21 -> 0
A66: D103121381 | B66: 0 | C66: Jeringa estéril desechable | D66: Ander Med | E66: 3mlluerlock21G×38mmTW (3mlluer lock21G×38mm TW) | F66: Importado | G66: Insumo | H66: Pza | I66: USD | J66: 46030 | K66: No | L66: =tblCatalogo[[#This Row],[Costo_Base]]*21 -> 0
A67: D103122251 | B67: 0 | C67: Jeringa estéril desechable | D67: Ander Med | E67: 3mlluerlock22G×25mmTW (3mlluer lock22G×25mm TW) | F67: Importado | G67: Insumo | H67: Pza | I67: USD | J67: 46030 | K67: No | L67: =tblCatalogo[[#This Row],[Costo_Base]]*21 -> 0
A68: D103122321 | B68: 0 | C68: Jeringa estéril desechable | D68: Ander Med | E68: 3mlluerlock22G×32mmTW (3mlluer lock22G×32mm TW) | F68: Importado | G68: Insumo | H68: Pza | I68: USD | J68: 46030 | K68: No | L68: =tblCatalogo[[#This Row],[Costo_Base]]*21 -> 0
A69: D103123201 | B69: 0 | C69: Jeringa estéril desechable | D69: Ander Med | E69: 3mlluerlock23G×20mmTW (3mlluer lock23G×20mm TW) | F69: Importado | G69: Insumo | H69: Pza | I69: USD | J69: 46030 | K69: No | L69: =tblCatalogo[[#This Row],[Costo_Base]]*21 -> 0
A70: D103123251 | B70: 0 | C70: Jeringa estéril desechable | D70: Ander Med | E70: 3mlluerlock23G×25mmTW (3mlluer lock23G×25mm TW) | F70: Importado | G70: Insumo | H70: Pza | I70: USD | J70: 46030 | K70: No | L70: =tblCatalogo[[#This Row],[Costo_Base]]*21 -> 0
A71: D103123321 | B71: 0 | C71: Jeringa estéril desechable | D71: Ander Med | E71: 3mlluerlock23G×32mmTW (3mlluer lock23G×32mm TW) | F71: Importado | G71: Insumo | H71: Pza | I71: USD | J71: 46030 | K71: No | L71: =tblCatalogo[[#This Row],[Costo_Base]]*21 -> 0
A72: D103125160 | B72: 0 | C72: Jeringa estéril desechable | D72: Ander Med | E72: 3mlluerlock25G×16mmRW (3mlluer lock25G×16mm RW) | F72: Importado | G72: Insumo | H72: Pza | I72: USD | J72: 46030 | K72: No | L72: =tblCatalogo[[#This Row],[Costo_Base]]*21 -> 0
A73: D103125200 | B73: 0 | C73: Jeringa estéril desechable | D73: Ander Med | E73: 3mlluerlock25G×20mmRW (3mlluer lock25G×20mm RW) | F73: Importado | G73: Insumo | H73: Pza | I73: USD | J73: 46030 | K73: No | L73: =tblCatalogo[[#This Row],[Costo_Base]]*21 -> 0
A74: D103125250 | B74: 0 | C74: Jeringa estéril desechable | D74: Ander Med | E74: 3mlluerlock25G×25mmRW (3mlluer lock25G×25mm RW) | F74: Importado | G74: Insumo | H74: Pza | I74: USD | J74: 46030 | K74: No | L74: =tblCatalogo[[#This Row],[Costo_Base]]*21 -> 0
... A193: MV01B-CTO-02 | B193: 1400 | C193: Localizador de venas con pantalla | D193: Medcaptain | E193: Navi-60 | F193: Importado | G193: Equipo | H193: Pza | I193: USD | J193: 46030 | K193: Si | L193: =tblCatalogo[[#This Row],[Costo_Base]]*21 -> 29400
A194: NPZ-WP-D3 | B194: N/A | C194: Set de infusión de volumenes medidos, cámara de bureta de 150 ml, dos conexiones libres de aguja, clamp Robert, con segmento de silicona libre de DEHP, de PVC, longitud: 300 cm | D194: Ander Med | E194: Set de infusión de volumenes medidos | F194: Importado | G194: Insumo | H194: Pza | I194: USD | J194: 46030 | K194: No | L194: =tblCatalogo[[#This Row],[Costo_Base]]*21 -> #VALUE!
A195: NPZ-W-S1 | B195: N/A | C195: Set de infusión convencional, con dos puertos libres de aguja, conector luer lock, clamp de rodillo, con segmento de silicon libre de DEHP, de PVC, longitud: 300 cm | D195: Ander Med | E195: Set de infusión convencional | F195: Importado | G195: Insumo | H195: Pza | I195: USD | J195: 46030 | K195: No | L195: =tblCatalogo[[#This Row],[Costo_Base]]*21 -> #VALUE!
A196: RP513 | B196: 59 | C196: Carro para bomba de infusión, con capacidad de carga de 18 kg, altura ajustable de 160 a 248 cm Carro para bomba de infusión ☆Material: aleación de aluminio ☆Capacidad de carga: 18 kg ☆Base: aleación de aluminio, 580 mm de diámetro, base en forma de estrella ☆Ruedas: ruedas médicas de 3 pulgadas ☆ Altura: 160-248 cm Ajustable ☆Sin cesta, CON SOPORTE PIEZAS | D196: TPX | E196: Accesorio | F196: Importado | G196: Equipo | H196: Pza | I196: USD | J196: 46030 | K196: Si | L196: =tblCatalogo[[#This Row],[Costo_Base]]*21 -> 1239
A197: RP513-M | B197: 6 | C197: Bracket de seguridad | D197: TPX | E197: Accesorio | F197: Importado | G197: Equipo | H197: Pza | I197: USD | J197: 46030 | K197: Si | L197: =tblCatalogo[[#This Row],[Costo_Base]]*21 -> 126
A198: RP513-3M | B198: 178 | C198: Carro para bomba de infusión, con capacidad de carga de 18 kg, soporta de 6 a 8 bombas | D198: TPX | E198: Accesorio | F198: Importado | G198: Equipo | H198: Pza | I198: USD | J198: 46030 | K198: Si | L198: =tblCatalogo[[#This Row],[Costo_Base]]*21 -> 3738
A199: 3001-00170-01 | B199: 5 | C199: 50ml cassette Cerulean | D199: Medcaptain | E199: AR2L-050 | F199: Importado | G199: Equipo | H199: Pza | I199: USD | J199: 46030 | K199: Si | L199: =tblCatalogo[[#This Row],[Costo_Base]]*21 -> 105
A200: 3001-00330-01 | B200: 5 | C200: 50ml cassette Transparent | D200: Medcaptain | E200: AR2L-050 | F200: Importado | G200: Equipo | H200: Pza | I200: USD | J200: 46030 | K200: Si | L200: =tblCatalogo[[#This Row],[Costo_Base]]*21 -> 105
A201: 3001-00350-01 | B201: 5 | C201: 50ml cassette Yellow | D201: Medcaptain | E201: AR2L-050 | F201: Importado | G201: Equipo | H201: Pza | I201: USD | J201: 46030 | K201: Si | L201: =tblCatalogo[[#This Row],[Costo_Base]]*21 -> 105
A202: 3001-00370-01 | B202: 5 | C202: 50ml cassette Grey | D202: Medcaptain | E202: AR2L-050 | F202: Importado | G202: Equipo | H202: Pza | I202: USD | J202: 46030 | K202: Si | L202: =tblCatalogo[[#This Row],[Costo_Base]]*21 -> 105
A203: 3001-00171-01 | B203: 5.5 | C203: 100ml cassette Cerulean | D203: Medcaptain | E203: AR2L-100 | F203: Importado | G203: Equipo | H203: Pza | I203: USD | J203: 46030 | K203: Si | L203: =tblCatalogo[[#This Row],[Costo_Base]]*21 -> 115.5
A204: 3001-00331-01 | B204: 5.5 | C204: 100ml cassette Transparent | D204: Medcaptain | E204: AR2L-100 | F204: Importado | G204: Equipo | H204: Pza | I204: USD | J204: 46030 | K204: Si | L204: =tblCatalogo[[#This Row],[Costo_Base]]*21 -> 115.5
...

Sheet PARAMETROS_IMPORTACION
A1: Concepto | B1: Tipo | C1: Valor | D1: Descripción | F1: NOTA
A2: Maritimo | B2: % | C2: 0.05 | D2: Porcentaje sobre costo base (en moneda base convertida a MXN) | F2: Ajusta estos parámetros globales. Si necesitas excepciones por SKU, se puede añadir una hoja de EXCEPCIONES.
A3: Aereo | B3: % | C3: 0.1 | D3: Porcentaje sobre costo base
A4: Arancel | B4: % | C4: 0.05 | D4: Porcentaje sobre costo base
A5: Honorarios_Aduanales | B5: % | C5: 0.0045 | D5: Monto fijo por unidad en MXN (ajústalo a tu realidad)
A6: Seguro | B6: % | C6: 0.006
A7: Mark_up | B7: % | C7: 0.1
A8: DTA | B8: % | C8: 0.008

Sheet TIPOS_CAMBIO
A1: Moneda | B1: TC_MXN | C1: Fuente/Notas | D1: Fecha
A2: MXN | B2: 1 | C2: Base | D2: 46021
A3: USD | B3: 21 | C3: Promedio +3 | D3: 46021
A4: EUR | B4: 22 | C4: Promedio +1 | D4: 46021
A5: GBP | B5: 25.5 | C5: Promedio +1 | D5: 46021

Sheet LANDED_COST
A1: SKU | B1: Transporte | C1: Origen | D1: Moneda | E1: Costo_Base | F1: TC_MXN | G1: Costo_Base_MXN | H1: Flete_% | I1: Seguro_% | J1: Arancel_% | K1: Mark_up_% | L1: DTA | M1: Honorarios_Aduanales | N1: Landed_Cost_MXN | O1: Mark_up
A2: D0031 | B2: Maritimo | C2: =_xlfn.XLOOKUP(A2,CATALOGO_PRODUCTOS!A:A,CATALOGO_PRODUCTOS!F:F,"",0) -> Importado | D2: =_xlfn.XLOOKUP(A2,CATALOGO_PRODUCTOS!A:A,CATALOGO_PRODUCTOS!I:I,"",0) -> USD | E2: =_xlfn.XLOOKUP(A2,CATALOGO_PRODUCTOS!A:A,CATALOGO_PRODUCTOS!B:B,0,0) -> 0.0235 | F2: =_xlfn.XLOOKUP(D2,TIPOS_CAMBIO!A:A,TIPOS_CAMBIO!B:B,"",0) -> 21 | G2: =$E2*$F2 -> 0.4935 | H2: =_xlfn.XLOOKUP($B$2,PARAMETROS_IMPORTACION!A:A,PARAMETROS_IMPORTACION!C:C,0,0) -> 0.05 | I2: =_xlfn.XLOOKUP("Seguro",PARAMETROS_IMPORTACION!A:A,PARAMETROS_IMPORTACION!C:C,0,0) -> 0.006 | J2: =_xlfn.XLOOKUP("Arancel",PARAMETROS_IMPORTACION!A:A,PARAMETROS_IMPORTACION!C:C,0,0) -> 0.05 | K2: =_xlfn.XLOOKUP("Mark_up",PARAMETROS_IMPORTACION!A:A,PARAMETROS_IMPORTACION!C:C,0,0) -> 0.1 | L2: =_xlfn.XLOOKUP("DTA",PARAMETROS_IMPORTACION!A:A,PARAMETROS_IMPORTACION!C:C,0,0) -> 0.008 | M2: =_xlfn.XLOOKUP("Honorarios_Aduanales",PARAMETROS_IMPORTACION!A:A,PARAMETROS_IMPORTACION!C:C,0,0) -> 0.0045 | N2: =IF($C2="Importado",$G2*(1+$H2+I2+$J2+$L2+$M2),$G2) -> 0.55197975 | O2: =N2 * (1 + K2) -> 0.60717773
A3: D0051 | B3: Maritimo | C3: =_xlfn.XLOOKUP(A3,CATALOGO_PRODUCTOS!A:A,CATALOGO_PRODUCTOS!F:F,"",0) -> Importado | D3: =_xlfn.XLOOKUP(A3,CATALOGO_PRODUCTOS!A:A,CATALOGO_PRODUCTOS!I:I,"",0) -> USD | E3: =_xlfn.XLOOKUP(A3,CATALOGO_PRODUCTOS!A:A,CATALOGO_PRODUCTOS!B:B,0,0) -> 0.029 | F3: =_xlfn.XLOOKUP(D3,TIPOS_CAMBIO!A:A,TIPOS_CAMBIO!B:B,"",0) -> 21 | G3: =$E3*$F3 -> 0.609 | H3: =_xlfn.XLOOKUP($B$3,PARAMETROS_IMPORTACION!A:A,PARAMETROS_IMPORTACION!C:C,0,0) -> 0.05 | I3: =_xlfn.XLOOKUP("Seguro",PARAMETROS_IMPORTACION!A:A,PARAMETROS_IMPORTACION!C:C,0,0) -> 0.006 | J3: =_xlfn.XLOOKUP("Arancel",PARAMETROS_IMPORTACION!A:A,PARAMETROS_IMPORTACION!C:C,0,0) -> 0.05 | K3: =_xlfn.XLOOKUP("Mark_up",PARAMETROS_IMPORTACION!A:A,PARAMETROS_IMPORTACION!C:C,0,0) -> 0.1 | L3: =_xlfn.XLOOKUP("DTA",PARAMETROS_IMPORTACION!A:A,PARAMETROS_IMPORTACION!C:C,0,0) -> 0.008 | M3: =_xlfn.XLOOKUP("Honorarios_Aduanales",PARAMETROS_IMPORTACION!A:A,PARAMETROS_IMPORTACION!C:C,0,0) -> 0.0045 | N3: =IF($C3="Importado",$G3*(1+$H3+I3+$J3+$L3+$M3),$G3) -> 0.6811665 | O3: =N3 * (1 + K3) -> 0.74928315
A4: D0101 | B4: Maritimo | C4: =_xlfn.XLOOKUP(A4,CATALOGO_PRODUCTOS!A:A,CATALOGO_PRODUCTOS!F:F,"",0) -> Importado | D4: =_xlfn.XLOOKUP(A4,CATALOGO_PRODUCTOS!A:A,CATALOGO_PRODUCTOS!I:I,"",0) -> USD | E4: =_xlfn.XLOOKUP(A4,CATALOGO_PRODUCTOS!A:A,CATALOGO_PRODUCTOS!B:B,0,0) -> 0.037 | F4: =_xlfn.XLOOKUP(D4,TIPOS_CAMBIO!A:A,TIPOS_CAMBIO!B:B,"",0) -> 21 | G4: =$E4*$F4 -> 0.777 | H4: =_xlfn.XLOOKUP($B$4,PARAMETROS_IMPORTACION!A:A,PARAMETROS_IMPORTACION!C:C,0,0) -> 0.05 | I4: =_xlfn.XLOOKUP("Seguro",PARAMETROS_IMPORTACION!A:A,PARAMETROS_IMPORTACION!C:C,0,0) -> 0.006 | J4: =_xlfn.XLOOKUP("Arancel",PARAMETROS_IMPORTACION!A:A,PARAMETROS_IMPORTACION!C:C,0,0) -> 0.05 | K4: =_xlfn.XLOOKUP("Mark_up",PARAMETROS_IMPORTACION!A:A,PARAMETROS_IMPORTACION!C:C,0,0) -> 0.1 | L4: =_xlfn.XLOOKUP("DTA",PARAMETROS_IMPORTACION!A:A,PARAMETROS_IMPORTACION!C:C,0,0) -> 0.008 | M4: =_xlfn.XLOOKUP("Honorarios_Aduanales",PARAMETROS_IMPORTACION!A:A,PARAMETROS_IMPORTACION!C:C,0,0) -> 0.0045 | N4: =IF($C4="Importado",$G4*(1+$H4+I4+$J4+$L4+$M4),$G4) -> 0.8690745 | O4: =N4 * (1 + K4) -> 0.95598195
A5: D0031 | B5: Aereo | C5: =_xlfn.XLOOKUP(A5,CATALOGO_PRODUCTOS!A:A,CATALOGO_PRODUCTOS!F:F,"",0) -> Importado | D5: =_xlfn.XLOOKUP(A5,CATALOGO_PRODUCTOS!A:A,CATALOGO_PRODUCTOS!I:I,"",0) -> USD | E5: =_xlfn.XLOOKUP(A5,CATALOGO_PRODUCTOS!A:A,CATALOGO_PRODUCTOS!B:B,0,0) -> 0.0235 | F5: =_xlfn.XLOOKUP(D5,TIPOS_CAMBIO!A:A,TIPOS_CAMBIO!B:B,"",0) -> 21 | G5: =$E5*$F5 -> 0.4935 | H5: =_xlfn.XLOOKUP($B$5,PARAMETROS_IMPORTACION!A:A,PARAMETROS_IMPORTACION!C:C,0,0) -> 0.1 | I5: =_xlfn.XLOOKUP("Seguro",PARAMETROS_IMPORTACION!A:A,PARAMETROS_IMPORTACION!C:C,0,0) -> 0.006 | J5: =_xlfn.XLOOKUP("Arancel",PARAMETROS_IMPORTACION!A:A,PARAMETROS_IMPORTACION!C:C,0,0) -> 0.05 | K5: =_xlfn.XLOOKUP("Mark_up",PARAMETROS_IMPORTACION!A:A,PARAMETROS_IMPORTACION!C:C,0,0) -> 0.1 | L5: =_xlfn.XLOOKUP("DTA",PARAMETROS_IMPORTACION!A:A,PARAMETROS_IMPORTACION!C:C,0,0) -> 0.008 | M5: =_xlfn.XLOOKUP("Honorarios_Aduanales",PARAMETROS_IMPORTACION!A:A,PARAMETROS_IMPORTACION!C:C,0,0) -> 0.0045 | N5: =IF($C5="Importado",$G5*(1+$H5+I5+$J5+$L5+$M5),$G5) -> 0.57665475 | O5: =N5 * (1 + K5) -> 0.63432023
A6: D0051 | B6: Aereo | C6: =_xlfn.XLOOKUP(A6,CATALOGO_PRODUCTOS!A:A,CATALOGO_PRODUCTOS!F:F,"",0) -> Importado | D6: =_xlfn.XLOOKUP(A6,CATALOGO_PRODUCTOS!A:A,CATALOGO_PRODUCTOS!I:I,"",0) -> USD | E6: =_xlfn.XLOOKUP(A6,CATALOGO_PRODUCTOS!A:A,CATALOGO_PRODUCTOS!B:B,0,0) -> 0.029 | F6: =_xlfn.XLOOKUP(D6,TIPOS_CAMBIO!A:A,TIPOS_CAMBIO!B:B,"",0) -> 21 | G6: =$E6*$F6 -> 0.609 | H6: =_xlfn.XLOOKUP($B$6,PARAMETROS_IMPORTACION!A:A,PARAMETROS_IMPORTACION!C:C,0,0) -> 0.1 | I6: =_xlfn.XLOOKUP("Seguro",PARAMETROS_IMPORTACION!A:A,PARAMETROS_IMPORTACION!C:C,0,0) -> 0.006 | J6: =_xlfn.XLOOKUP("Arancel",PARAMETROS_IMPORTACION!A:A,PARAMETROS_IMPORTACION!C:C,0,0) -> 0.05 | K6: =_xlfn.XLOOKUP("Mark_up",PARAMETROS_IMPORTACION!A:A,PARAMETROS_IMPORTACION!C:C,0,0) -> 0.1 | L6: =_xlfn.XLOOKUP("DTA",PARAMETROS_IMPORTACION!A:A,PARAMETROS_IMPORTACION!C:C,0,0) -> 0.008 | M6: =_xlfn.XLOOKUP("Honorarios_Aduanales",PARAMETROS_IMPORTACION!A:A,PARAMETROS_IMPORTACION!C:C,0,0) -> 0.0045 | N6: =IF($C6="Importado",$G6*(1+$H6+I6+$J6+$L6+$M6),$G6) -> 0.7116165 | O6: =N6 * (1 + K6) -> 0.78277815
A7: D0101 | B7: Aereo | C7: =_xlfn.XLOOKUP(A7,CATALOGO_PRODUCTOS!A:A,CATALOGO_PRODUCTOS!F:F,"",0) -> Importado | D7: =_xlfn.XLOOKUP(A7,CATALOGO_PRODUCTOS!A:A,CATALOGO_PRODUCTOS!I:I,"",0) -> USD | E7: =_xlfn.XLOOKUP(A7,CATALOGO_PRODUCTOS!A:A,CATALOGO_PRODUCTOS!B:B,0,0) -> 0.037 | F7: =_xlfn.XLOOKUP(D7,TIPOS_CAMBIO!A:A,TIPOS_CAMBIO!B:B,"",0) -> 21 | G7: =$E7*$F7 -> 0.777 | H7: =_xlfn.XLOOKUP($B$7,PARAMETROS_IMPORTACION!A:A,PARAMETROS_IMPORTACION!C:C,0,0) -> 0.1 | I7: =_xlfn.XLOOKUP("Seguro",PARAMETROS_IMPORTACION!A:A,PARAMETROS_IMPORTACION!C:C,0,0) -> 0.006 | J7: =_xlfn.XLOOKUP("Arancel",PARAMETROS_IMPORTACION!A:A,PARAMETROS_IMPORTACION!C:C,0,0) -> 0.05 | K7: =_xlfn.XLOOKUP("Mark_up",PARAMETROS_IMPORTACION!A:A,PARAMETROS_IMPORTACION!C:C,0,0) -> 0.1 | L7: =_xlfn.XLOOKUP("DTA",PARAMETROS_IMPORTACION!A:A,PARAMETROS_IMPORTACION!C:C,0,0) -> 0.008 | M7: =_xlfn.XLOOKUP("Honorarios_Aduanales",PARAMETROS_IMPORTACION!A:A,PARAMETROS_IMPORTACION!C:C,0,0) -> 0.0045 | N7: =IF($C7="Importado",$G7*(1+$H7+I7+$J7+$L7+$M7),$G7) -> 0.9079245 | O7: =N7 * (1 + K7) -> 0.99871695

Sheet CONTROL_VERSIONES
A1: Fecha | B1: Versión | C1: Cambio / Motivo | D1: Responsable
